[0m09:00:15.699448 [debug] [MainThread]: Sending event: {'category': 'dbt', 'action': 'invocation', 'label': 'start', 'context': [<snowplow_tracker.self_describing_json.SelfDescribingJson object at 0x000001CD1AA09E70>, <snowplow_tracker.self_describing_json.SelfDescribingJson object at 0x000001CD1AB7AA10>, <snowplow_tracker.self_describing_json.SelfDescribingJson object at 0x000001CD1C276D70>]}


============================== 09:00:15.714357 | da9165fc-7af9-4b7e-a4d8-e5f58b0301a9 ==============================
[0m09:00:15.714357 [info ] [MainThread]: Running with dbt=1.10.4
[0m09:00:15.715361 [debug] [MainThread]: running dbt with arguments {'printer_width': '80', 'indirect_selection': 'eager', 'log_cache_events': 'False', 'write_json': 'True', 'partial_parse': 'True', 'cache_selected_only': 'False', 'profiles_dir': 'C:\\Users\\fikre\\.dbt', 'fail_fast': 'False', 'warn_error': 'None', 'log_path': 'logs', 'debug': 'False', 'version_check': 'True', 'use_colors': 'True', 'use_experimental_parser': 'False', 'no_print': 'None', 'quiet': 'False', 'empty': 'None', 'warn_error_options': 'WarnErrorOptionsV2(error=[], warn=[], silence=[])', 'introspect': 'True', 'static_parser': 'True', 'log_format': 'default', 'target_path': 'None', 'invocation_command': 'dbt init telegram_analytics', 'send_anonymous_usage_stats': 'True'}
[0m09:00:15.976433 [info ] [MainThread]: Creating dbt configuration folder at C:\Users\fikre\.dbt
[0m09:00:15.990504 [debug] [MainThread]: Starter project path: C:\Users\fikre\Telegram-Analytics-Pipeline\venv\lib\site-packages\dbt\include\starter_project
[0m09:00:16.061516 [info ] [MainThread]: 
Your new dbt project "telegram_analytics" was created!

For more information on how to configure the profiles.yml file,
please consult the dbt documentation here:

  https://docs.getdbt.com/docs/configure-your-profile

One more thing:

Need help? Don't hesitate to reach out to us via GitHub issues or on Slack:

  https://community.getdbt.com/

Happy modeling!

[0m09:00:16.062493 [info ] [MainThread]: Setting up your profile.
[0m09:12:41.732093 [error] [MainThread]: Encountered an error:
list index out of range
[0m09:12:41.734111 [error] [MainThread]: Traceback (most recent call last):
  File "C:\Users\fikre\Telegram-Analytics-Pipeline\venv\lib\site-packages\dbt\cli\requires.py", line 161, in wrapper
    result, success = func(*args, **kwargs)
  File "C:\Users\fikre\Telegram-Analytics-Pipeline\venv\lib\site-packages\dbt\cli\requires.py", line 111, in wrapper
    return func(*args, **kwargs)
  File "C:\Users\fikre\Telegram-Analytics-Pipeline\venv\lib\site-packages\dbt\cli\main.py", line 483, in init
    results = task.run()
  File "C:\Users\fikre\Telegram-Analytics-Pipeline\venv\lib\site-packages\dbt\task\init.py", line 346, in run
    self.setup_profile(profile_name)
  File "C:\Users\fikre\Telegram-Analytics-Pipeline\venv\lib\site-packages\dbt\task\init.py", line 261, in setup_profile
    adapter = self.ask_for_adapter_choice()
  File "C:\Users\fikre\Telegram-Analytics-Pipeline\venv\lib\site-packages\dbt\task\init.py", line 243, in ask_for_adapter_choice
    return available_adapters[numeric_choice - 1]
IndexError: list index out of range

[0m09:12:41.735093 [debug] [MainThread]: Command `dbt init` failed at 09:12:41.735093 after 746.18 seconds
[0m09:12:41.735093 [debug] [MainThread]: Sending event: {'category': 'dbt', 'action': 'invocation', 'label': 'end', 'context': [<snowplow_tracker.self_describing_json.SelfDescribingJson object at 0x000001CD1AA09E70>, <snowplow_tracker.self_describing_json.SelfDescribingJson object at 0x000001CD1C96E0B0>, <snowplow_tracker.self_describing_json.SelfDescribingJson object at 0x000001CD1C96DD50>]}
[0m09:12:41.736602 [debug] [MainThread]: Flushing usage events
[0m09:12:42.951739 [debug] [MainThread]: An error was encountered while trying to flush usage events
[0m09:12:50.891924 [debug] [MainThread]: Sending event: {'category': 'dbt', 'action': 'invocation', 'label': 'start', 'context': [<snowplow_tracker.self_describing_json.SelfDescribingJson object at 0x0000029AA1509E40>, <snowplow_tracker.self_describing_json.SelfDescribingJson object at 0x0000029AA326F670>, <snowplow_tracker.self_describing_json.SelfDescribingJson object at 0x0000029AA34682E0>]}


============================== 09:12:50.894940 | d596406d-131b-41b1-92ff-9ad9e27e31b0 ==============================
[0m09:12:50.894940 [info ] [MainThread]: Running with dbt=1.10.4
[0m09:12:50.897452 [debug] [MainThread]: running dbt with arguments {'printer_width': '80', 'indirect_selection': 'eager', 'write_json': 'True', 'log_cache_events': 'False', 'partial_parse': 'True', 'cache_selected_only': 'False', 'profiles_dir': 'C:\\Users\\fikre\\.dbt', 'fail_fast': 'False', 'version_check': 'True', 'log_path': 'logs', 'warn_error': 'None', 'debug': 'False', 'use_colors': 'True', 'use_experimental_parser': 'False', 'no_print': 'None', 'quiet': 'False', 'empty': 'None', 'warn_error_options': 'WarnErrorOptionsV2(error=[], warn=[], silence=[])', 'invocation_command': 'dbt init telegram_analytics', 'introspect': 'True', 'static_parser': 'True', 'target_path': 'None', 'log_format': 'default', 'send_anonymous_usage_stats': 'True'}
[0m09:12:50.911591 [info ] [MainThread]: A project called telegram_analytics already exists here.
[0m09:12:50.913571 [debug] [MainThread]: Command `dbt init` succeeded at 09:12:50.913571 after 0.10 seconds
[0m09:12:50.914594 [debug] [MainThread]: Sending event: {'category': 'dbt', 'action': 'invocation', 'label': 'end', 'context': [<snowplow_tracker.self_describing_json.SelfDescribingJson object at 0x0000029AA1509E40>, <snowplow_tracker.self_describing_json.SelfDescribingJson object at 0x0000029AA326F670>, <snowplow_tracker.self_describing_json.SelfDescribingJson object at 0x0000029AA3469420>]}
[0m09:12:50.915571 [debug] [MainThread]: Flushing usage events
[0m09:12:51.650027 [debug] [MainThread]: An error was encountered while trying to flush usage events
[0m09:12:56.600935 [debug] [MainThread]: Sending event: {'category': 'dbt', 'action': 'invocation', 'label': 'start', 'context': [<snowplow_tracker.self_describing_json.SelfDescribingJson object at 0x000001A647959E70>, <snowplow_tracker.self_describing_json.SelfDescribingJson object at 0x000001A6498EE350>, <snowplow_tracker.self_describing_json.SelfDescribingJson object at 0x000001A6498ED660>]}


============================== 09:12:56.604939 | 7416e245-afac-4914-be3d-df3e66611cbf ==============================
[0m09:12:56.604939 [info ] [MainThread]: Running with dbt=1.10.4
[0m09:12:56.604939 [debug] [MainThread]: running dbt with arguments {'printer_width': '80', 'indirect_selection': 'eager', 'write_json': 'True', 'log_cache_events': 'False', 'partial_parse': 'True', 'cache_selected_only': 'False', 'warn_error': 'None', 'version_check': 'True', 'debug': 'False', 'log_path': 'logs', 'profiles_dir': 'C:\\Users\\fikre\\.dbt', 'fail_fast': 'False', 'use_colors': 'True', 'use_experimental_parser': 'False', 'no_print': 'None', 'quiet': 'False', 'empty': 'None', 'log_format': 'default', 'introspect': 'True', 'static_parser': 'True', 'invocation_command': 'dbt docs generate', 'target_path': 'None', 'warn_error_options': 'WarnErrorOptionsV2(error=[], warn=[], silence=[])', 'send_anonymous_usage_stats': 'True'}
[0m09:12:56.606444 [error] [MainThread]: Encountered an error:
Runtime Error
  No dbt_project.yml found at expected path C:\Users\fikre\Telegram-Analytics-Pipeline\dbt_project.yml
  Verify that each entry within packages.yml (and their transitive dependencies) contains a file named dbt_project.yml
  
[0m09:12:56.607452 [debug] [MainThread]: Command `dbt docs generate` failed at 09:12:56.607452 after 0.08 seconds
[0m09:12:56.608480 [debug] [MainThread]: Sending event: {'category': 'dbt', 'action': 'invocation', 'label': 'end', 'context': [<snowplow_tracker.self_describing_json.SelfDescribingJson object at 0x000001A647959E70>, <snowplow_tracker.self_describing_json.SelfDescribingJson object at 0x000001A6498B3850>, <snowplow_tracker.self_describing_json.SelfDescribingJson object at 0x000001A6498EC190>]}
[0m09:12:56.609451 [debug] [MainThread]: Flushing usage events
[0m09:12:57.361703 [debug] [MainThread]: An error was encountered while trying to flush usage events
[0m09:13:07.893778 [debug] [MainThread]: Sending event: {'category': 'dbt', 'action': 'invocation', 'label': 'start', 'context': [<snowplow_tracker.self_describing_json.SelfDescribingJson object at 0x0000021DCCE39EA0>, <snowplow_tracker.self_describing_json.SelfDescribingJson object at 0x0000021DCDD1F520>, <snowplow_tracker.self_describing_json.SelfDescribingJson object at 0x0000021DCDD1FC70>]}


============================== 09:13:07.897577 | 09e09a64-7002-4116-baa2-87b15f3075ee ==============================
[0m09:13:07.897577 [info ] [MainThread]: Running with dbt=1.10.4
[0m09:13:07.898553 [debug] [MainThread]: running dbt with arguments {'printer_width': '80', 'indirect_selection': 'eager', 'log_cache_events': 'False', 'write_json': 'True', 'partial_parse': 'True', 'cache_selected_only': 'False', 'warn_error': 'None', 'debug': 'False', 'profiles_dir': 'C:\\Users\\fikre\\.dbt', 'log_path': 'logs', 'fail_fast': 'False', 'version_check': 'True', 'use_colors': 'True', 'use_experimental_parser': 'False', 'empty': 'None', 'quiet': 'False', 'no_print': 'None', 'log_format': 'default', 'invocation_command': 'dbt docs serve', 'static_parser': 'True', 'warn_error_options': 'WarnErrorOptionsV2(error=[], warn=[], silence=[])', 'target_path': 'None', 'introspect': 'True', 'send_anonymous_usage_stats': 'True'}
[0m09:13:07.898553 [error] [MainThread]: Encountered an error:
Runtime Error
  No dbt_project.yml found at expected path C:\Users\fikre\Telegram-Analytics-Pipeline\dbt_project.yml
  Verify that each entry within packages.yml (and their transitive dependencies) contains a file named dbt_project.yml
  
[0m09:13:07.899737 [debug] [MainThread]: Command `dbt docs serve` failed at 09:13:07.899737 after 0.09 seconds
[0m09:13:07.900773 [debug] [MainThread]: Sending event: {'category': 'dbt', 'action': 'invocation', 'label': 'end', 'context': [<snowplow_tracker.self_describing_json.SelfDescribingJson object at 0x0000021DCCE39EA0>, <snowplow_tracker.self_describing_json.SelfDescribingJson object at 0x0000021DCDD1FE80>, <snowplow_tracker.self_describing_json.SelfDescribingJson object at 0x0000021DCDD1F520>]}
[0m09:13:07.900773 [debug] [MainThread]: Flushing usage events
[0m09:13:08.608558 [debug] [MainThread]: An error was encountered while trying to flush usage events
